[2021-04-18 16:40:01,335] {taskinstance.py:851} INFO - Dependencies all met for <TaskInstance: fetch_kc_crime_data-v0.1.fetch_crime_window 2021-04-18T16:39:55.182189+00:00 [queued]>
[2021-04-18 16:40:01,351] {taskinstance.py:851} INFO - Dependencies all met for <TaskInstance: fetch_kc_crime_data-v0.1.fetch_crime_window 2021-04-18T16:39:55.182189+00:00 [queued]>
[2021-04-18 16:40:01,352] {taskinstance.py:1042} INFO - 
--------------------------------------------------------------------------------
[2021-04-18 16:40:01,353] {taskinstance.py:1043} INFO - Starting attempt 1 of 1
[2021-04-18 16:40:01,355] {taskinstance.py:1044} INFO - 
--------------------------------------------------------------------------------
[2021-04-18 16:40:01,387] {taskinstance.py:1063} INFO - Executing <Task(PythonOperator): fetch_crime_window> on 2021-04-18T16:39:55.182189+00:00
[2021-04-18 16:40:01,393] {standard_task_runner.py:52} INFO - Started process 1392 to run task
[2021-04-18 16:40:01,398] {standard_task_runner.py:76} INFO - Running: ['airflow', 'tasks', 'run', 'fetch_kc_crime_data-v0.1', 'fetch_crime_window', '2021-04-18T16:39:55.182189+00:00', '--job-id', '6', '--pool', 'default_pool', '--raw', '--subdir', 'DAGS_FOLDER/fetch_kc_crime_data-v0.1.py', '--cfg-path', '/tmp/tmpevkykid8', '--error-file', '/tmp/tmpjx8rkn5q']
[2021-04-18 16:40:01,402] {standard_task_runner.py:77} INFO - Job 6: Subtask fetch_crime_window
[2021-04-18 16:40:01,490] {logging_mixin.py:104} INFO - Running <TaskInstance: fetch_kc_crime_data-v0.1.fetch_crime_window 2021-04-18T16:39:55.182189+00:00 [running]> on host 441e26371bd5
[2021-04-18 16:40:01,587] {taskinstance.py:1257} INFO - Exporting the following env vars:
AIRFLOW_CTX_DAG_OWNER=airflow
AIRFLOW_CTX_DAG_ID=fetch_kc_crime_data-v0.1
AIRFLOW_CTX_TASK_ID=fetch_crime_window
AIRFLOW_CTX_EXECUTION_DATE=2021-04-18T16:39:55.182189+00:00
AIRFLOW_CTX_DAG_RUN_ID=manual__2021-04-18T16:39:55.182189+00:00
[2021-04-18 16:40:01,611] {taskinstance.py:1455} ERROR - 
Traceback (most recent call last):
  File "/home/airflow/.local/lib/python3.6/site-packages/airflow/models/taskinstance.py", line 1112, in _run_raw_task
    self._prepare_and_execute_task_with_callbacks(context, task)
  File "/home/airflow/.local/lib/python3.6/site-packages/airflow/models/taskinstance.py", line 1285, in _prepare_and_execute_task_with_callbacks
    result = self._execute_task(context, task_copy)
  File "/home/airflow/.local/lib/python3.6/site-packages/airflow/models/taskinstance.py", line 1315, in _execute_task
    result = task_copy.execute(context=context)
  File "/home/airflow/.local/lib/python3.6/site-packages/airflow/operators/python.py", line 117, in execute
    return_value = self.execute_callable()
  File "/home/airflow/.local/lib/python3.6/site-packages/airflow/operators/python.py", line 128, in execute_callable
    return self.python_callable(*self.op_args, **self.op_kwargs)
  File "/opt/airflow/dags/fetch_kc_crime_data-v0.1.py", line 38, in fetch_crime_window
    connection = pg_hook.get_conn()
  File "/home/airflow/.local/lib/python3.6/site-packages/airflow/providers/postgres/hooks/postgres.py", line 83, in get_conn
    conn = self.connection or self.get_connection(conn_id)
  File "/home/airflow/.local/lib/python3.6/site-packages/airflow/hooks/base.py", line 73, in get_connection
    "XXXXXXXX" if conn.password else None,
  File "/home/airflow/.local/lib/python3.6/site-packages/sqlalchemy/orm/attributes.py", line 365, in __get__
    retval = self.descriptor.__get__(instance, owner)
  File "/home/airflow/.local/lib/python3.6/site-packages/airflow/models/connection.py", line 213, in get_password
    return fernet.decrypt(bytes(self._password, 'utf-8')).decode()
  File "/home/airflow/.local/lib/python3.6/site-packages/cryptography/fernet.py", line 194, in decrypt
    raise InvalidToken
cryptography.fernet.InvalidToken
[2021-04-18 16:40:01,615] {taskinstance.py:1503} INFO - Marking task as FAILED. dag_id=fetch_kc_crime_data-v0.1, task_id=fetch_crime_window, execution_date=20210418T163955, start_date=20210418T164001, end_date=20210418T164001
[2021-04-18 16:40:01,696] {local_task_job.py:146} INFO - Task exited with return code 1
